Workbook
Name Alloys: Validation!$H$16:$H$24
Name alt_pg1_foot: '4b. Quote no pricing'!$B$52:$H$52
Name alt_pg2_foot: '4b. Quote no pricing'!$B$108:$H$108
Name alt_pg3_foot: '4b. Quote no pricing'!$B$163:$H$163
Name alt_pg4_foot: '4b. Quote no pricing'!$B$218:$H$218
Name alt_pg5_foot: '4b. Quote no pricing'!$B$273:$H$273
Name alt_pg6_foot: '4b. Quote no pricing'!$B$328:$H$328
Name Ano_Fin_Cost: 'Pricing Matrix'!#REF!
Name ap: Validation!$R$19
Name ap_or_pp: Validation!$R$2:$T$11
Name AP_PP_factor: 'Pricing Matrix'!$K$5
Name Applicator: Validation!$R$2:$R$11
Name Applicator_ano: Validation!$V$2:$V$5
Name attention: '1.Project Details'!$B$12
Name colour_code: Colour_Groups!$C$4:$D$94
Name COLOURS: Colour_Groups!$A$4:$D$94
Name customer: '1.Project Details'!$B$11
Name Delivery: 'Pricing Matrix'!$H$3
Name file_source: BOM_Import!$G$1
Name Fin_Cost_Price: 'Pricing Matrix'!$E$44
Name Fin_Sell_Price: 'Pricing Matrix'!$F$44
Name FinBulk_Cost_Price: 'Pricing Matrix'!$E$46
Name FinBulk_Sell_Price: 'Pricing Matrix'!$F$46
Name finish: '1.Project Details'!$B$32
Name finish_anodised: Validation!$AB$2:$AB$4
Name finish_applicator_value: '1.Project Details'!$B$26
Name finish_code_value: '1.Project Details'!$E$30
Name finish_common: BOM_Import!$L$11
Name Finish_Custom_Code: '1.Project Details'!$E$31
Name Finish_Custom_Name: '1.Project Details'!$B$31
Name finish_group_value: '1.Project Details'!$B$28
Name finish_groups: Validation!$R$2:$U$11
Name finish_list: BOM_Import!$K$11:$K$15
Name finish_mill: Validation!$W$2
Name finish_name_value: '1.Project Details'!$B$30
Name finish_pc_capral: Validation!$X$2:$X$7
Name finish_pc_other: Validation!$Z$2:$Z$5
Name finish_perimeter: Validation!$R$15:$R$16
Name finish_type: Validation!$S$15:$S$17
Name finish_type_value: '1.Project Details'!$B$24
Name FinNonBulk_Cost_Price: 'Pricing Matrix'!$E$47
Name FinNonBulk_Sell_Price: 'Pricing Matrix'!$F$47
Name GRP1_Long: Colour_Groups!$C$4:$C$31
Name GRP2_Long: Colour_Groups!$C$32:$C$43
Name Grp20_Long: Colour_Groups!$C$90:$C$91
Name Grp25_Long: Colour_Groups!$C$92:$C$93
Name Grp3_Long: Colour_Groups!$C$44:$C$56
Name Grp4_Long: Colour_Groups!$C$57:$C$63
Name Grp5_Long: Colour_Groups!$C$64:$C$89
Name GrpNA_Long: Colour_Groups!$C$3
Name GrpPOA_Long: Colour_Groups!$C$94
Name hide_twopage: '2b.Quote MF ALT'!$G$52:$J$52
Name hide_twopage: '4b. Quote no pricing'!$G$52:$H$52
Name hide_twopage: '2.Quote'!$G$52:$J$52
Name local_logo: '1.Project Details'!$B$23
Name local_logo_opt: Validation!$E$2:$E$4
Name Market_Segment: Validation!$A$2:$A$13
Name metalcost: 'Pricing Matrix'!$O$5
Name MF_ALT: '1.Project Details'!$E$24
Name No: Validation!$X$13

Sheet DATA
A1: Section | B1: Basic material | C1: RD | D1: Mass / M | E1: AP | F1: PP | G1: Mat_Grp | H1: PH | I1: PH Text | J1: External Material Group | K1: subsill | L1: Wall Thickness | M1: TB (No, PLS, PDB) | N1: SQ01 Report
A2: =N9 -> SUNDRY-1 | B2: =O9 -> Sundry description - 1 | C2: N | D2: =P9 -> 1 | E2: =Q9 -> 200 | F2: =R9 -> 200 | G2: =IF(LEFT(Table5[[#This Row],[Section]],3)="ETB","AE3000","") | K2: =_xlfn.IFNA(VLOOKUP(Table5[[#This Row],[Section]],SubSill_Tier,2,FALSE),0) -> 0 | L2: =IFERROR(IF(LEFT(G2,2)="AI",IF(_xlfn.NUMBERVALUE(IFERROR(LEFT(IF(ISERROR(FIND("X",UPPER(B2))),UPPER(B2),RIGHT(UPPER(B2),LEN(UPPER(B2))-FIND("~",SUBSTITUTE(UPPER(B2),"X","~",LEN(UPPER(B2))-LEN(SUBSTITUTE(UPPER(B2),"X","")))))),FIND(" ",IF(ISERROR(FIND("X",UPPER(B2))),UPPER(B2),RIGHT(UPPER(B2),LEN(UPPER(B2))-FIND("~",SUBSTITUTE(UPPER(B2),"X","~",LEN(UPPER(B2))-LEN(SUBSTITUTE(UPPER(B2),"X","")))))),1)-1),IF(ISERROR(FIND("X",UPPER(B2))),UPPER(B2),RIGHT(UPPER(B2),LEN(UPPER(B2))-FIND("~",SUBSTITUTE(UPPER(B2),"X","~",LEN(UPPER(B2))-LEN(SUBSTITUTE(UPPER(B2),"X",""))))))),".")>=5,"Wall",""),""),"") | M2: {=_xlfn.IFS(NOT(ISERROR(VLOOKUP(Table5[[#This Row],[Section]],TB_notTB,1,FALSE))),"No",LEFT(Table5[[#This Row],[Section]],3)="ETB","PLS",LEFT(Table5[[#This Row],[Section]],1)="7","PDB",NOT(ISBLANK(Table5[[#This Row],[Section]])),"No")} -> No | N2: SQ01 - Pricing - 1_MAT_INFO
A3: =N10 -> SUNDRY-2 | B3: =O10 -> Sundry description - 2 | C3: N | D3: =P10 -> 0 | E3: =Q10 -> 0 | F3: =R10 -> 0 | G3: =IF(LEFT(Table5[[#This Row],[Section]],3)="ETB","AE3000","") | K3: =_xlfn.IFNA(VLOOKUP(Table5[[#This Row],[Section]],SubSill_Tier,2,FALSE),0) -> 0 | L3: =IFERROR(IF(LEFT(G3,2)="AI",IF(_xlfn.NUMBERVALUE(IFERROR(LEFT(IF(ISERROR(FIND("X",UPPER(B3))),UPPER(B3),RIGHT(UPPER(B3),LEN(UPPER(B3))-FIND("~",SUBSTITUTE(UPPER(B3),"X","~",LEN(UPPER(B3))-LEN(SUBSTITUTE(UPPER(B3),"X","")))))),FIND(" ",IF(ISERROR(FIND("X",UPPER(B3))),UPPER(B3),RIGHT(UPPER(B3),LEN(UPPER(B3))-FIND("~",SUBSTITUTE(UPPER(B3),"X","~",LEN(UPPER(B3))-LEN(SUBSTITUTE(UPPER(B3),"X","")))))),1)-1),IF(ISERROR(FIND("X",UPPER(B3))),UPPER(B3),RIGHT(UPPER(B3),LEN(UPPER(B3))-FIND("~",SUBSTITUTE(UPPER(B3),"X","~",LEN(UPPER(B3))-LEN(SUBSTITUTE(UPPER(B3),"X",""))))))),".")>=5,"Wall",""),""),"") | M3: {=_xlfn.IFS(NOT(ISERROR(VLOOKUP(Table5[[#This Row],[Section]],TB_notTB,1,FALSE))),"No",LEFT(Table5[[#This Row],[Section]],3)="ETB","PLS",LEFT(Table5[[#This Row],[Section]],1)="7","PDB",NOT(ISBLANK(Table5[[#This Row],[Section]])),"No")} -> No | N3: Layout = Andrew
A4: =N11 -> SUNDRY-3 | B4: =O11 -> Sundry description - 3 | C4: N | D4: =P11 -> 0 | E4: =Q11 -> 0 | F4: =R11 -> 0 | G4: =IF(LEFT(Table5[[#This Row],[Section]],3)="ETB","AE3000","") | K4: =_xlfn.IFNA(VLOOKUP(Table5[[#This Row],[Section]],SubSill_Tier,2,FALSE),0) -> 0 | L4: =IFERROR(IF(LEFT(G4,2)="AI",IF(_xlfn.NUMBERVALUE(IFERROR(LEFT(IF(ISERROR(FIND("X",UPPER(B4))),UPPER(B4),RIGHT(UPPER(B4),LEN(UPPER(B4))-FIND("~",SUBSTITUTE(UPPER(B4),"X","~",LEN(UPPER(B4))-LEN(SUBSTITUTE(UPPER(B4),"X","")))))),FIND(" ",IF(ISERROR(FIND("X",UPPER(B4))),UPPER(B4),RIGHT(UPPER(B4),LEN(UPPER(B4))-FIND("~",SUBSTITUTE(UPPER(B4),"X","~",LEN(UPPER(B4))-LEN(SUBSTITUTE(UPPER(B4),"X","")))))),1)-1),IF(ISERROR(FIND("X",UPPER(B4))),UPPER(B4),RIGHT(UPPER(B4),LEN(UPPER(B4))-FIND("~",SUBSTITUTE(UPPER(B4),"X","~",LEN(UPPER(B4))-LEN(SUBSTITUTE(UPPER(B4),"X",""))))))),".")>=5,"Wall",""),""),"") | M4: {=_xlfn.IFS(NOT(ISERROR(VLOOKUP(Table5[[#This Row],[Section]],TB_notTB,1,FALSE))),"No",LEFT(Table5[[#This Row],[Section]],3)="ETB","PLS",LEFT(Table5[[#This Row],[Section]],1)="7","PDB",NOT(ISBLANK(Table5[[#This Row],[Section]])),"No")} -> No | N4: Export by ZDIE | O4: EDGE: Export by ZALC & ZALS for AE3500 to AE3999. Convert Material to number. Change last column to be MPG instead of Material Price Group
A5: =N12 -> SUNDRY-4 | B5: =O12 -> Sundry description - 4 | C5: N | D5: =P12 -> 0 | E5: =Q12 -> 0 | F5: =R12 -> 0 | G5: =IF(LEFT(Table5[[#This Row],[Section]],3)="ETB","AE3000","") | K5: =_xlfn.IFNA(VLOOKUP(Table5[[#This Row],[Section]],SubSill_Tier,2,FALSE),0) -> 0 | L5: =IFERROR(IF(LEFT(G5,2)="AI",IF(_xlfn.NUMBERVALUE(IFERROR(LEFT(IF(ISERROR(FIND("X",UPPER(B5))),UPPER(B5),RIGHT(UPPER(B5),LEN(UPPER(B5))-FIND("~",SUBSTITUTE(UPPER(B5),"X","~",LEN(UPPER(B5))-LEN(SUBSTITUTE(UPPER(B5),"X","")))))),FIND(" ",IF(ISERROR(FIND("X",UPPER(B5))),UPPER(B5),RIGHT(UPPER(B5),LEN(UPPER(B5))-FIND("~",SUBSTITUTE(UPPER(B5),"X","~",LEN(UPPER(B5))-LEN(SUBSTITUTE(UPPER(B5),"X","")))))),1)-1),IF(ISERROR(FIND("X",UPPER(B5))),UPPER(B5),RIGHT(UPPER(B5),LEN(UPPER(B5))-FIND("~",SUBSTITUTE(UPPER(B5),"X","~",LEN(UPPER(B5))-LEN(SUBSTITUTE(UPPER(B5),"X",""))))))),".")>=5,"Wall",""),""),"") | M5: {=_xlfn.IFS(NOT(ISERROR(VLOOKUP(Table5[[#This Row],[Section]],TB_notTB,1,FALSE))),"No",LEFT(Table5[[#This Row],[Section]],3)="ETB","PLS",LEFT(Table5[[#This Row],[Section]],1)="7","PDB",NOT(ISBLANK(Table5[[#This Row],[Section]])),"No")} -> No | N5: Export to AE*, AG*, AI*, AR* (each separately)
A6: =N13 -> SUNDRY-5 | B6: =O13 -> Sundry description - 5 | C6: N | D6: =P13 -> 0 | E6: =Q13 -> 0 | F6: =R13 -> 0 | G6: =IF(LEFT(Table5[[#This Row],[Section]],3)="ETB","AE3000","") | K6: =_xlfn.IFNA(VLOOKUP(Table5[[#This Row],[Section]],SubSill_Tier,2,FALSE),0) -> 0 | L6: =IFERROR(IF(LEFT(G6,2)="AI",IF(_xlfn.NUMBERVALUE(IFERROR(LEFT(IF(ISERROR(FIND("X",UPPER(B6))),UPPER(B6),RIGHT(UPPER(B6),LEN(UPPER(B6))-FIND("~",SUBSTITUTE(UPPER(B6),"X","~",LEN(UPPER(B6))-LEN(SUBSTITUTE(UPPER(B6),"X","")))))),FIND(" ",IF(ISERROR(FIND("X",UPPER(B6))),UPPER(B6),RIGHT(UPPER(B6),LEN(UPPER(B6))-FIND("~",SUBSTITUTE(UPPER(B6),"X","~",LEN(UPPER(B6))-LEN(SUBSTITUTE(UPPER(B6),"X","")))))),1)-1),IF(ISERROR(FIND("X",UPPER(B6))),UPPER(B6),RIGHT(UPPER(B6),LEN(UPPER(B6))-FIND("~",SUBSTITUTE(UPPER(B6),"X","~",LEN(UPPER(B6))-LEN(SUBSTITUTE(UPPER(B6),"X",""))))))),".")>=5,"Wall",""),""),"") | M6: {=_xlfn.IFS(NOT(ISERROR(VLOOKUP(Table5[[#This Row],[Section]],TB_notTB,1,FALSE))),"No",LEFT(Table5[[#This Row],[Section]],3)="ETB","PLS",LEFT(Table5[[#This Row],[Section]],1)="7","PDB",NOT(ISBLANK(Table5[[#This Row],[Section]])),"No")} -> No | N6: Select View button and Excel in place. Copy & Paste into a new book, sort by section then paste into here
A7: =N14 -> SUNDRY-6 | B7: =O14 -> Sundry description - 6 | C7: N | D7: =P14 -> 0 | E7: =Q14 -> 0 | F7: =R14 -> 0 | G7: =IF(LEFT(Table5[[#This Row],[Section]],3)="ETB","AE3000","") | K7: =_xlfn.IFNA(VLOOKUP(Table5[[#This Row],[Section]],SubSill_Tier,2,FALSE),0) -> 0 | L7: =IFERROR(IF(LEFT(G7,2)="AI",IF(_xlfn.NUMBERVALUE(IFERROR(LEFT(IF(ISERROR(FIND("X",UPPER(B7))),UPPER(B7),RIGHT(UPPER(B7),LEN(UPPER(B7))-FIND("~",SUBSTITUTE(UPPER(B7),"X","~",LEN(UPPER(B7))-LEN(SUBSTITUTE(UPPER(B7),"X","")))))),FIND(" ",IF(ISERROR(FIND("X",UPPER(B7))),UPPER(B7),RIGHT(UPPER(B7),LEN(UPPER(B7))-FIND("~",SUBSTITUTE(UPPER(B7),"X","~",LEN(UPPER(B7))-LEN(SUBSTITUTE(UPPER(B7),"X","")))))),1)-1),IF(ISERROR(FIND("X",UPPER(B7))),UPPER(B7),RIGHT(UPPER(B7),LEN(UPPER(B7))-FIND("~",SUBSTITUTE(UPPER(B7),"X","~",LEN(UPPER(B7))-LEN(SUBSTITUTE(UPPER(B7),"X",""))))))),".")>=5,"Wall",""),""),"") | M7: {=_xlfn.IFS(NOT(ISERROR(VLOOKUP(Table5[[#This Row],[Section]],TB_notTB,1,FALSE))),"No",LEFT(Table5[[#This Row],[Section]],3)="ETB","PLS",LEFT(Table5[[#This Row],[Section]],1)="7","PDB",NOT(ISBLANK(Table5[[#This Row],[Section]])),"No")} -> No | N7: Ensure formula in Mat_Grp column extends all way down to last section
A8: =N15 -> SUNDRY-7 | B8: =O15 -> Sundry description - 7 | C8: N | D8: =P15 -> 0 | E8: =Q15 -> 0 | F8: =R15 -> 0 | G8: =IF(LEFT(Table5[[#This Row],[Section]],3)="ETB","AE3000","") | K8: =_xlfn.IFNA(VLOOKUP(Table5[[#This Row],[Section]],SubSill_Tier,2,FALSE),0) -> 0 | L8: =IFERROR(IF(LEFT(G8,2)="AI",IF(_xlfn.NUMBERVALUE(IFERROR(LEFT(IF(ISERROR(FIND("X",UPPER(B8))),UPPER(B8),RIGHT(UPPER(B8),LEN(UPPER(B8))-FIND("~",SUBSTITUTE(UPPER(B8),"X","~",LEN(UPPER(B8))-LEN(SUBSTITUTE(UPPER(B8),"X","")))))),FIND(" ",IF(ISERROR(FIND("X",UPPER(B8))),UPPER(B8),RIGHT(UPPER(B8),LEN(UPPER(B8))-FIND("~",SUBSTITUTE(UPPER(B8),"X","~",LEN(UPPER(B8))-LEN(SUBSTITUTE(UPPER(B8),"X","")))))),1)-1),IF(ISERROR(FIND("X",UPPER(B8))),UPPER(B8),RIGHT(UPPER(B8),LEN(UPPER(B8))-FIND("~",SUBSTITUTE(UPPER(B8),"X","~",LEN(UPPER(B8))-LEN(SUBSTITUTE(UPPER(B8),"X",""))))))),".")>=5,"Wall",""),""),"") | M8: {=_xlfn.IFS(NOT(ISERROR(VLOOKUP(Table5[[#This Row],[Section]],TB_notTB,1,FALSE))),"No",LEFT(Table5[[#This Row],[Section]],3)="ETB","PLS",LEFT(Table5[[#This Row],[Section]],1)="7","PDB",NOT(ISBLANK(Table5[[#This Row],[Section]])),"No")} -> No | N8: SUNDRY ITEMS | O8: SUNDRY DESCRIPTIONS | P8: Mass / M | Q8: AP | R8: PP
A9: =N16 -> SUNDRY-8 | B9: =O16 -> Sundry description - 8 | C9: N | D9: =P16 -> 0 | E9: =Q16 -> 0 | F9: =R16 -> 0 | G9: =IF(LEFT(Table5[[#This Row],[Section]],3)="ETB","AE3000","") | K9: =_xlfn.IFNA(VLOOKUP(Table5[[#This Row],[Section]],SubSill_Tier,2,FALSE),0) -> 0 | L9: =IFERROR(IF(LEFT(G9,2)="AI",IF(_xlfn.NUMBERVALUE(IFERROR(LEFT(IF(ISERROR(FIND("X",UPPER(B9))),UPPER(B9),RIGHT(UPPER(B9),LEN(UPPER(B9))-FIND("~",SUBSTITUTE(UPPER(B9),"X","~",LEN(UPPER(B9))-LEN(SUBSTITUTE(UPPER(B9),"X","")))))),FIND(" ",IF(ISERROR(FIND("X",UPPER(B9))),UPPER(B9),RIGHT(UPPER(B9),LEN(UPPER(B9))-FIND("~",SUBSTITUTE(UPPER(B9),"X","~",LEN(UPPER(B9))-LEN(SUBSTITUTE(UPPER(B9),"X","")))))),1)-1),IF(ISERROR(FIND("X",UPPER(B9))),UPPER(B9),RIGHT(UPPER(B9),LEN(UPPER(B9))-FIND("~",SUBSTITUTE(UPPER(B9),"X","~",LEN(UPPER(B9))-LEN(SUBSTITUTE(UPPER(B9),"X",""))))))),".")>=5,"Wall",""),""),"") | M9: {=_xlfn.IFS(NOT(ISERROR(VLOOKUP(Table5[[#This Row],[Section]],TB_notTB,1,FALSE))),"No",LEFT(Table5[[#This Row],[Section]],3)="ETB","PLS",LEFT(Table5[[#This Row],[Section]],1)="7","PDB",NOT(ISBLANK(Table5[[#This Row],[Section]])),"No")} -> No | N9: SUNDRY-1 | O9: Sundry description - 1 | P9: 1 | Q9: 200 | R9: 200
A10: =N17 -> SUNDRY-9 | B10: =O17 -> Sundry description - 9 | C10: N | D10: =P17 -> 0 | E10: =Q17 -> 0 | F10: =R17 -> 0 | G10: =IF(LEFT(Table5[[#This Row],[Section]],3)="ETB","AE3000","") | K10: =_xlfn.IFNA(VLOOKUP(Table5[[#This Row],[Section]],SubSill_Tier,2,FALSE),0) -> 0 | L10: =IFERROR(IF(LEFT(G10,2)="AI",IF(_xlfn.NUMBERVALUE(IFERROR(LEFT(IF(ISERROR(FIND("X",UPPER(B10))),UPPER(B10),RIGHT(UPPER(B10),LEN(UPPER(B10))-FIND("~",SUBSTITUTE(UPPER(B10),"X","~",LEN(UPPER(B10))-LEN(SUBSTITUTE(UPPER(B10),"X","")))))),FIND(" ",IF(ISERROR(FIND("X",UPPER(B10))),UPPER(B10),RIGHT(UPPER(B10),LEN(UPPER(B10))-FIND("~",SUBSTITUTE(UPPER(B10),"X","~",LEN(UPPER(B10))-LEN(SUBSTITUTE(UPPER(B10),"X","")))))),1)-1),IF(ISERROR(FIND("X",UPPER(B10))),UPPER(B10),RIGHT(UPPER(B10),LEN(UPPER(B10))-FIND("~",SUBSTITUTE(UPPER(B10),"X","~",LEN(UPPER(B10))-LEN(SUBSTITUTE(UPPER(B10),"X",""))))))),".")>=5,"Wall",""),""),"") | M10: {=_xlfn.IFS(NOT(ISERROR(VLOOKUP(Table5[[#This Row],[Section]],TB_notTB,1,FALSE))),"No",LEFT(Table5[[#This Row],[Section]],3)="ETB","PLS",LEFT(Table5[[#This Row],[Section]],1)="7","PDB",NOT(ISBLANK(Table5[[#This Row],[Section]])),"No")} -> No | N10: SUNDRY-2 | O10: Sundry description - 2
A11: =N18 -> SUNDRY-10 | B11: =O18 -> Sundry description - 10 | C11: N | D11: =P18 -> 0 | E11: =Q18 -> 0 | F11: =R18 -> 0 | G11: =IF(LEFT(Table5[[#This Row],[Section]],3)="ETB","AE3000","") | K11: =_xlfn.IFNA(VLOOKUP(Table5[[#This Row],[Section]],SubSill_Tier,2,FALSE),0) -> 0 | L11: =IFERROR(IF(LEFT(G11,2)="AI",IF(_xlfn.NUMBERVALUE(IFERROR(LEFT(IF(ISERROR(FIND("X",UPPER(B11))),UPPER(B11),RIGHT(UPPER(B11),LEN(UPPER(B11))-FIND("~",SUBSTITUTE(UPPER(B11),"X","~",LEN(UPPER(B11))-LEN(SUBSTITUTE(UPPER(B11),"X","")))))),FIND(" ",IF(ISERROR(FIND("X",UPPER(B11))),UPPER(B11),RIGHT(UPPER(B11),LEN(UPPER(B11))-FIND("~",SUBSTITUTE(UPPER(B11),"X","~",LEN(UPPER(B11))-LEN(SUBSTITUTE(UPPER(B11),"X","")))))),1)-1),IF(ISERROR(FIND("X",UPPER(B11))),UPPER(B11),RIGHT(UPPER(B11),LEN(UPPER(B11))-FIND("~",SUBSTITUTE(UPPER(B11),"X","~",LEN(UPPER(B11))-LEN(SUBSTITUTE(UPPER(B11),"X",""))))))),".")>=5,"Wall",""),""),"") | M11: {=_xlfn.IFS(NOT(ISERROR(VLOOKUP(Table5[[#This Row],[Section]],TB_notTB,1,FALSE))),"No",LEFT(Table5[[#This Row],[Section]],3)="ETB","PLS",LEFT(Table5[[#This Row],[Section]],1)="7","PDB",NOT(ISBLANK(Table5[[#This Row],[Section]])),"No")} -> No | N11: SUNDRY-3 | O11: Sundry description - 3
A12: =N19 -> SUNDRY-11 | B12: =O19 -> Sundry description - 11 | C12: N | D12: =P19 -> 0 | E12: =Q19 -> 0 | F12: =R19 -> 0 | G12: =IF(LEFT(Table5[[#This Row],[Section]],3)="ETB","AE3000","") | K12: =_xlfn.IFNA(VLOOKUP(Table5[[#This Row],[Section]],SubSill_Tier,2,FALSE),0) -> 0 | L12: =IFERROR(IF(LEFT(G12,2)="AI",IF(_xlfn.NUMBERVALUE(IFERROR(LEFT(IF(ISERROR(FIND("X",UPPER(B12))),UPPER(B12),RIGHT(UPPER(B12),LEN(UPPER(B12))-FIND("~",SUBSTITUTE(UPPER(B12),"X","~",LEN(UPPER(B12))-LEN(SUBSTITUTE(UPPER(B12),"X","")))))),FIND(" ",IF(ISERROR(FIND("X",UPPER(B12))),UPPER(B12),RIGHT(UPPER(B12),LEN(UPPER(B12))-FIND("~",SUBSTITUTE(UPPER(B12),"X","~",LEN(UPPER(B12))-LEN(SUBSTITUTE(UPPER(B12),"X","")))))),1)-1),IF(ISERROR(FIND("X",UPPER(B12))),UPPER(B12),RIGHT(UPPER(B12),LEN(UPPER(B12))-FIND("~",SUBSTITUTE(UPPER(B12),"X","~",LEN(UPPER(B12))-LEN(SUBSTITUTE(UPPER(B12),"X",""))))))),".")>=5,"Wall",""),""),"") | M12: {=_xlfn.IFS(NOT(ISERROR(VLOOKUP(Table5[[#This Row],[Section]],TB_notTB,1,FALSE))),"No",LEFT(Table5[[#This Row],[Section]],3)="ETB","PLS",LEFT(Table5[[#This Row],[Section]],1)="7","PDB",NOT(ISBLANK(Table5[[#This Row],[Section]])),"No")} -> No | N12: SUNDRY-4 | O12: Sundry description - 4
A13: =N20 -> SUNDRY-12 | B13: =O20 -> Sundry description - 12 | C13: N | D13: =P20 -> 0 | E13: =Q20 -> 0 | F13: =R20 -> 0 | G13: =IF(LEFT(Table5[[#This Row],[Section]],3)="ETB","AE3000","") | K13: =_xlfn.IFNA(VLOOKUP(Table5[[#This Row],[Section]],SubSill_Tier,2,FALSE),0) -> 0 | L13: =IFERROR(IF(LEFT(G13,2)="AI",IF(_xlfn.NUMBERVALUE(IFERROR(LEFT(IF(ISERROR(FIND("X",UPPER(B13))),UPPER(B13),RIGHT(UPPER(B13),LEN(UPPER(B13))-FIND("~",SUBSTITUTE(UPPER(B13),"X","~",LEN(UPPER(B13))-LEN(SUBSTITUTE(UPPER(B13),"X","")))))),FIND(" ",IF(ISERROR(FIND("X",UPPER(B13))),UPPER(B13),RIGHT(UPPER(B13),LEN(UPPER(B13))-FIND("~",SUBSTITUTE(UPPER(B13),"X","~",LEN(UPPER(B13))-LEN(SUBSTITUTE(UPPER(B13),"X","")))))),1)-1),IF(ISERROR(FIND("X",UPPER(B13))),UPPER(B13),RIGHT(UPPER(B13),LEN(UPPER(B13))-FIND("~",SUBSTITUTE(UPPER(B13),"X","~",LEN(UPPER(B13))-LEN(SUBSTITUTE(UPPER(B13),"X",""))))))),".")>=5,"Wall",""),""),"") | M13: {=_xlfn.IFS(NOT(ISERROR(VLOOKUP(Table5[[#This Row],[Section]],TB_notTB,1,FALSE))),"No",LEFT(Table5[[#This Row],[Section]],3)="ETB","PLS",LEFT(Table5[[#This Row],[Section]],1)="7","PDB",NOT(ISBLANK(Table5[[#This Row],[Section]])),"No")} -> No | N13: SUNDRY-5 | O13: Sundry description - 5
A14: =N21 -> SUNDRY-13 | B14: =O21 -> Sundry description - 13 | C14: N | D14: =P21 -> 0 | E14: =Q21 -> 0 | F14: =R21 -> 0 | G14: =IF(LEFT(Table5[[#This Row],[Section]],3)="ETB","AE3000","") | K14: =_xlfn.IFNA(VLOOKUP(Table5[[#This Row],[Section]],SubSill_Tier,2,FALSE),0) -> 0 | L14: =IFERROR(IF(LEFT(G14,2)="AI",IF(_xlfn.NUMBERVALUE(IFERROR(LEFT(IF(ISERROR(FIND("X",UPPER(B14))),UPPER(B14),RIGHT(UPPER(B14),LEN(UPPER(B14))-FIND("~",SUBSTITUTE(UPPER(B14),"X","~",LEN(UPPER(B14))-LEN(SUBSTITUTE(UPPER(B14),"X","")))))),FIND(" ",IF(ISERROR(FIND("X",UPPER(B14))),UPPER(B14),RIGHT(UPPER(B14),LEN(UPPER(B14))-FIND("~",SUBSTITUTE(UPPER(B14),"X","~",LEN(UPPER(B14))-LEN(SUBSTITUTE(UPPER(B14),"X","")))))),1)-1),IF(ISERROR(FIND("X",UPPER(B14))),UPPER(B14),RIGHT(UPPER(B14),LEN(UPPER(B14))-FIND("~",SUBSTITUTE(UPPER(B14),"X","~",LEN(UPPER(B14))-LEN(SUBSTITUTE(UPPER(B14),"X",""))))))),".")>=5,"Wall",""),""),"") | M14: {=_xlfn.IFS(NOT(ISERROR(VLOOKUP(Table5[[#This Row],[Section]],TB_notTB,1,FALSE))),"No",LEFT(Table5[[#This Row],[Section]],3)="ETB","PLS",LEFT(Table5[[#This Row],[Section]],1)="7","PDB",NOT(ISBLANK(Table5[[#This Row],[Section]])),"No")} -> No | N14: SUNDRY-6 | O14: Sundry description - 6
A15: =N22 -> SUNDRY-14 | B15: =O22 -> Sundry description - 14 | C15: N | D15: =P22 -> 0 | E15: =Q22 -> 0 | F15: =R22 -> 0 | G15: =IF(LEFT(Table5[[#This Row],[Section]],3)="ETB","AE3000","") | K15: =_xlfn.IFNA(VLOOKUP(Table5[[#This Row],[Section]],SubSill_Tier,2,FALSE),0) -> 0 | L15: =IFERROR(IF(LEFT(G15,2)="AI",IF(_xlfn.NUMBERVALUE(IFERROR(LEFT(IF(ISERROR(FIND("X",UPPER(B15))),UPPER(B15),RIGHT(UPPER(B15),LEN(UPPER(B15))-FIND("~",SUBSTITUTE(UPPER(B15),"X","~",LEN(UPPER(B15))-LEN(SUBSTITUTE(UPPER(B15),"X","")))))),FIND(" ",IF(ISERROR(FIND("X",UPPER(B15))),UPPER(B15),RIGHT(UPPER(B15),LEN(UPPER(B15))-FIND("~",SUBSTITUTE(UPPER(B15),"X","~",LEN(UPPER(B15))-LEN(SUBSTITUTE(UPPER(B15),"X","")))))),1)-1),IF(ISERROR(FIND("X",UPPER(B15))),UPPER(B15),RIGHT(UPPER(B15),LEN(UPPER(B15))-FIND("~",SUBSTITUTE(UPPER(B15),"X","~",LEN(UPPER(B15))-LEN(SUBSTITUTE(UPPER(B15),"X",""))))))),".")>=5,"Wall",""),""),"") | M15: {=_xlfn.IFS(NOT(ISERROR(VLOOKUP(Table5[[#This Row],[Section]],TB_notTB,1,FALSE))),"No",LEFT(Table5[[#This Row],[Section]],3)="ETB","PLS",LEFT(Table5[[#This Row],[Section]],1)="7","PDB",NOT(ISBLANK(Table5[[#This Row],[Section]])),"No")} -> No | N15: SUNDRY-7 | O15: Sundry description - 7
A16: =N23 -> SUNDRY-15 | B16: =O23 -> Sundry description - 15 | C16: N | D16: =P23 -> 0 | E16: =Q23 -> 0 | F16: =R23 -> 0 | G16: =IF(LEFT(Table5[[#This Row],[Section]],3)="ETB","AE3000","") | K16: =_xlfn.IFNA(VLOOKUP(Table5[[#This Row],[Section]],SubSill_Tier,2,FALSE),0) -> 0 | L16: =IFERROR(IF(LEFT(G16,2)="AI",IF(_xlfn.NUMBERVALUE(IFERROR(LEFT(IF(ISERROR(FIND("X",UPPER(B16))),UPPER(B16),RIGHT(UPPER(B16),LEN(UPPER(B16))-FIND("~",SUBSTITUTE(UPPER(B16),"X","~",LEN(UPPER(B16))-LEN(SUBSTITUTE(UPPER(B16),"X","")))))),FIND(" ",IF(ISERROR(FIND("X",UPPER(B16))),UPPER(B16),RIGHT(UPPER(B16),LEN(UPPER(B16))-FIND("~",SUBSTITUTE(UPPER(B16),"X","~",LEN(UPPER(B16))-LEN(SUBSTITUTE(UPPER(B16),"X","")))))),1)-1),IF(ISERROR(FIND("X",UPPER(B16))),UPPER(B16),RIGHT(UPPER(B16),LEN(UPPER(B16))-FIND("~",SUBSTITUTE(UPPER(B16),"X","~",LEN(UPPER(B16))-LEN(SUBSTITUTE(UPPER(B16),"X",""))))))),".")>=5,"Wall",""),""),"") | M16: {=_xlfn.IFS(NOT(ISERROR(VLOOKUP(Table5[[#This Row],[Section]],TB_notTB,1,FALSE))),"No",LEFT(Table5[[#This Row],[Section]],3)="ETB","PLS",LEFT(Table5[[#This Row],[Section]],1)="7","PDB",NOT(ISBLANK(Table5[[#This Row],[Section]])),"No")} -> No | N16: SUNDRY-8 | O16: Sundry description - 8
A17: =N24 -> SUNDRY-16 | B17: =O24 -> Sundry description - 16 | C17: N | D17: =P24 -> 0 | E17: =Q24 -> 0 | F17: =R24 -> 0 | G17: =IF(LEFT(Table5[[#This Row],[Section]],3)="ETB","AE3000","") | K17: =_xlfn.IFNA(VLOOKUP(Table5[[#This Row],[Section]],SubSill_Tier,2,FALSE),0) -> 0 | L17: =IFERROR(IF(LEFT(G17,2)="AI",IF(_xlfn.NUMBERVALUE(IFERROR(LEFT(IF(ISERROR(FIND("X",UPPER(B17))),UPPER(B17),RIGHT(UPPER(B17),LEN(UPPER(B17))-FIND("~",SUBSTITUTE(UPPER(B17),"X","~",LEN(UPPER(B17))-LEN(SUBSTITUTE(UPPER(B17),"X","")))))),FIND(" ",IF(ISERROR(FIND("X",UPPER(B17))),UPPER(B17),RIGHT(UPPER(B17),LEN(UPPER(B17))-FIND("~",SUBSTITUTE(UPPER(B17),"X","~",LEN(UPPER(B17))-LEN(SUBSTITUTE(UPPER(B17),"X","")))))),1)-1),IF(ISERROR(FIND("X",UPPER(B17))),UPPER(B17),RIGHT(UPPER(B17),LEN(UPPER(B17))-FIND("~",SUBSTITUTE(UPPER(B17),"X","~",LEN(UPPER(B17))-LEN(SUBSTITUTE(UPPER(B17),"X",""))))))),".")>=5,"Wall",""),""),"") | M17: {=_xlfn.IFS(NOT(ISERROR(VLOOKUP(Table5[[#This Row],[Section]],TB_notTB,1,FALSE))),"No",LEFT(Table5[[#This Row],[Section]],3)="ETB","PLS",LEFT(Table5[[#This Row],[Section]],1)="7","PDB",NOT(ISBLANK(Table5[[#This Row],[Section]])),"No")} -> No | N17: SUNDRY-9 | O17: Sundry description - 9
A18: =N25 -> SUNDRY-17 | B18: =O25 -> Sundry description - 17 | C18: N | D18: =P25 -> 0 | E18: =Q25 -> 0 | F18: =R25 -> 0 | G18: =IF(LEFT(Table5[[#This Row],[Section]],3)="ETB","AE3000","") | K18: =_xlfn.IFNA(VLOOKUP(Table5[[#This Row],[Section]],SubSill_Tier,2,FALSE),0) -> 0 | L18: =IFERROR(IF(LEFT(G18,2)="AI",IF(_xlfn.NUMBERVALUE(IFERROR(LEFT(IF(ISERROR(FIND("X",UPPER(B18))),UPPER(B18),RIGHT(UPPER(B18),LEN(UPPER(B18))-FIND("~",SUBSTITUTE(UPPER(B18),"X","~",LEN(UPPER(B18))-LEN(SUBSTITUTE(UPPER(B18),"X","")))))),FIND(" ",IF(ISERROR(FIND("X",UPPER(B18))),UPPER(B18),RIGHT(UPPER(B18),LEN(UPPER(B18))-FIND("~",SUBSTITUTE(UPPER(B18),"X","~",LEN(UPPER(B18))-LEN(SUBSTITUTE(UPPER(B18),"X","")))))),1)-1),IF(ISERROR(FIND("X",UPPER(B18))),UPPER(B18),RIGHT(UPPER(B18),LEN(UPPER(B18))-FIND("~",SUBSTITUTE(UPPER(B18),"X","~",LEN(UPPER(B18))-LEN(SUBSTITUTE(UPPER(B18),"X",""))))))),".")>=5,"Wall",""),""),"") | M18: {=_xlfn.IFS(NOT(ISERROR(VLOOKUP(Table5[[#This Row],[Section]],TB_notTB,1,FALSE))),"No",LEFT(Table5[[#This Row],[Section]],3)="ETB","PLS",LEFT(Table5[[#This Row],[Section]],1)="7","PDB",NOT(ISBLANK(Table5[[#This Row],[Section]])),"No")} -> No | N18: SUNDRY-10 | O18: Sundry description - 10
A19: =N26 -> SUNDRY-18 | B19: =O26 -> Sundry description - 18 | C19: N | D19: =P26 -> 0 | E19: =Q26 -> 0 | F19: =R26 -> 0 | G19: =IF(LEFT(Table5[[#This Row],[Section]],3)="ETB","AE3000","") | K19: =_xlfn.IFNA(VLOOKUP(Table5[[#This Row],[Section]],SubSill_Tier,2,FALSE),0) -> 0 | L19: =IFERROR(IF(LEFT(G19,2)="AI",IF(_xlfn.NUMBERVALUE(IFERROR(LEFT(IF(ISERROR(FIND("X",UPPER(B19))),UPPER(B19),RIGHT(UPPER(B19),LEN(UPPER(B19))-FIND("~",SUBSTITUTE(UPPER(B19),"X","~",LEN(UPPER(B19))-LEN(SUBSTITUTE(UPPER(B19),"X","")))))),FIND(" ",IF(ISERROR(FIND("X",UPPER(B19))),UPPER(B19),RIGHT(UPPER(B19),LEN(UPPER(B19))-FIND("~",SUBSTITUTE(UPPER(B19),"X","~",LEN(UPPER(B19))-LEN(SUBSTITUTE(UPPER(B19),"X","")))))),1)-1),IF(ISERROR(FIND("X",UPPER(B19))),UPPER(B19),RIGHT(UPPER(B19),LEN(UPPER(B19))-FIND("~",SUBSTITUTE(UPPER(B19),"X","~",LEN(UPPER(B19))-LEN(SUBSTITUTE(UPPER(B19),"X",""))))))),".")>=5,"Wall",""),""),"") | M19: {=_xlfn.IFS(NOT(ISERROR(VLOOKUP(Table5[[#This Row],[Section]],TB_notTB,1,FALSE))),"No",LEFT(Table5[[#This Row],[Section]],3)="ETB","PLS",LEFT(Table5[[#This Row],[Section]],1)="7","PDB",NOT(ISBLANK(Table5[[#This Row],[Section]])),"No")} -> No | N19: SUNDRY-11 | O19: Sundry description - 11
A20: =N27 -> SUNDRY-19 | B20: =O27 -> Sundry description - 19 | C20: N | D20: =P27 -> 0 | E20: =Q27 -> 0 | F20: =R27 -> 0 | G20: =IF(LEFT(Table5[[#This Row],[Section]],3)="ETB","AE3000","") | K20: =_xlfn.IFNA(VLOOKUP(Table5[[#This Row],[Section]],SubSill_Tier,2,FALSE),0) -> 0 | L20: =IFERROR(IF(LEFT(G20,2)="AI",IF(_xlfn.NUMBERVALUE(IFERROR(LEFT(IF(ISERROR(FIND("X",UPPER(B20))),UPPER(B20),RIGHT(UPPER(B20),LEN(UPPER(B20))-FIND("~",SUBSTITUTE(UPPER(B20),"X","~",LEN(UPPER(B20))-LEN(SUBSTITUTE(UPPER(B20),"X","")))))),FIND(" ",IF(ISERROR(FIND("X",UPPER(B20))),UPPER(B20),RIGHT(UPPER(B20),LEN(UPPER(B20))-FIND("~",SUBSTITUTE(UPPER(B20),"X","~",LEN(UPPER(B20))-LEN(SUBSTITUTE(UPPER(B20),"X","")))))),1)-1),IF(ISERROR(FIND("X",UPPER(B20))),UPPER(B20),RIGHT(UPPER(B20),LEN(UPPER(B20))-FIND("~",SUBSTITUTE(UPPER(B20),"X","~",LEN(UPPER(B20))-LEN(SUBSTITUTE(UPPER(B20),"X",""))))))),".")>=5,"Wall",""),""),"") | M20: {=_xlfn.IFS(NOT(ISERROR(VLOOKUP(Table5[[#This Row],[Section]],TB_notTB,1,FALSE))),"No",LEFT(Table5[[#This Row],[Section]],3)="ETB","PLS",LEFT(Table5[[#This Row],[Section]],1)="7","PDB",NOT(ISBLANK(Table5[[#This Row],[Section]])),"No")} -> No | N20: SUNDRY-12 | O20: Sundry description - 12
A21: =N28 -> SUNDRY-20 | B21: =O28 -> Sundry description - 20 | C21: N | D21: =P28 -> 0 | E21: =Q28 -> 0 | F21: =R28 -> 0 | G21: =IF(LEFT(Table5[[#This Row],[Section]],3)="ETB","AE3000","") | K21: =_xlfn.IFNA(VLOOKUP(Table5[[#This Row],[Section]],SubSill_Tier,2,FALSE),0) -> 0 | L21: =IFERROR(IF(LEFT(G21,2)="AI",IF(_xlfn.NUMBERVALUE(IFERROR(LEFT(IF(ISERROR(FIND("X",UPPER(B21))),UPPER(B21),RIGHT(UPPER(B21),LEN(UPPER(B21))-FIND("~",SUBSTITUTE(UPPER(B21),"X","~",LEN(UPPER(B21))-LEN(SUBSTITUTE(UPPER(B21),"X","")))))),FIND(" ",IF(ISERROR(FIND("X",UPPER(B21))),UPPER(B21),RIGHT(UPPER(B21),LEN(UPPER(B21))-FIND("~",SUBSTITUTE(UPPER(B21),"X","~",LEN(UPPER(B21))-LEN(SUBSTITUTE(UPPER(B21),"X","")))))),1)-1),IF(ISERROR(FIND("X",UPPER(B21))),UPPER(B21),RIGHT(UPPER(B21),LEN(UPPER(B21))-FIND("~",SUBSTITUTE(UPPER(B21),"X","~",LEN(UPPER(B21))-LEN(SUBSTITUTE(UPPER(B21),"X",""))))))),".")>=5,"Wall",""),""),"") | M21: {=_xlfn.IFS(NOT(ISERROR(VLOOKUP(Table5[[#This Row],[Section]],TB_notTB,1,FALSE))),"No",LEFT(Table5[[#This Row],[Section]],3)="ETB","PLS",LEFT(Table5[[#This Row],[Section]],1)="7","PDB",NOT(ISBLANK(Table5[[#This Row],[Section]])),"No")} -> No | N21: SUNDRY-13 | O21: Sundry description - 13
A22: =N29 -> SUNDRY-21 | B22: =O29 -> Sundry description - 21 | C22: N | D22: 0 | E22: 0 | F22: 0 | G22: =IF(LEFT(Table5[[#This Row],[Section]],3)="ETB","AE3000","") | K22: =_xlfn.IFNA(VLOOKUP(Table5[[#This Row],[Section]],SubSill_Tier,2,FALSE),0) -> 0 | L22: =IFERROR(IF(LEFT(G22,2)="AI",IF(_xlfn.NUMBERVALUE(IFERROR(LEFT(IF(ISERROR(FIND("X",UPPER(B22))),UPPER(B22),RIGHT(UPPER(B22),LEN(UPPER(B22))-FIND("~",SUBSTITUTE(UPPER(B22),"X","~",LEN(UPPER(B22))-LEN(SUBSTITUTE(UPPER(B22),"X","")))))),FIND(" ",IF(ISERROR(FIND("X",UPPER(B22))),UPPER(B22),RIGHT(UPPER(B22),LEN(UPPER(B22))-FIND("~",SUBSTITUTE(UPPER(B22),"X","~",LEN(UPPER(B22))-LEN(SUBSTITUTE(UPPER(B22),"X","")))))),1)-1),IF(ISERROR(FIND("X",UPPER(B22))),UPPER(B22),RIGHT(UPPER(B22),LEN(UPPER(B22))-FIND("~",SUBSTITUTE(UPPER(B22),"X","~",LEN(UPPER(B22))-LEN(SUBSTITUTE(UPPER(B22),"X",""))))))),".")>=5,"Wall",""),""),"") | M22: {=_xlfn.IFS(NOT(ISERROR(VLOOKUP(Table5[[#This Row],[Section]],TB_notTB,1,FALSE))),"No",LEFT(Table5[[#This Row],[Section]],3)="ETB","PLS",LEFT(Table5[[#This Row],[Section]],1)="7","PDB",NOT(ISBLANK(Table5[[#This Row],[Section]])),"No")} -> No | N22: SUNDRY-14 | O22: Sundry description - 14
A23: =N30 -> SUNDRY-22 | B23: =O30 -> Sundry description - 22 | C23: N | D23: 0 | E23: 0 | F23: 0 | G23: =IF(LEFT(Table5[[#This Row],[Section]],3)="ETB","AE3000","") | K23: =_xlfn.IFNA(VLOOKUP(Table5[[#This Row],[Section]],SubSill_Tier,2,FALSE),0) -> 0 | L23: =IFERROR(IF(LEFT(G23,2)="AI",IF(_xlfn.NUMBERVALUE(IFERROR(LEFT(IF(ISERROR(FIND("X",UPPER(B23))),UPPER(B23),RIGHT(UPPER(B23),LEN(UPPER(B23))-FIND("~",SUBSTITUTE(UPPER(B23),"X","~",LEN(UPPER(B23))-LEN(SUBSTITUTE(UPPER(B23),"X","")))))),FIND(" ",IF(ISERROR(FIND("X",UPPER(B23))),UPPER(B23),RIGHT(UPPER(B23),LEN(UPPER(B23))-FIND("~",SUBSTITUTE(UPPER(B23),"X","~",LEN(UPPER(B23))-LEN(SUBSTITUTE(UPPER(B23),"X","")))))),1)-1),IF(ISERROR(FIND("X",UPPER(B23))),UPPER(B23),RIGHT(UPPER(B23),LEN(UPPER(B23))-FIND("~",SUBSTITUTE(UPPER(B23),"X","~",LEN(UPPER(B23))-LEN(SUBSTITUTE(UPPER(B23),"X",""))))))),".")>=5,"Wall",""),""),"") | M23: {=_xlfn.IFS(NOT(ISERROR(VLOOKUP(Table5[[#This Row],[Section]],TB_notTB,1,FALSE))),"No",LEFT(Table5[[#This Row],[Section]],3)="ETB","PLS",LEFT(Table5[[#This Row],[Section]],1)="7","PDB",NOT(ISBLANK(Table5[[#This Row],[Section]])),"No")} -> No | N23: SUNDRY-15 | O23: Sundry description - 15
A24: =N31 -> SUNDRY-23 | B24: =O31 -> Sundry description - 23 | C24: N | D24: 0 | E24: 0 | F24: 0 | G24: =IF(LEFT(Table5[[#This Row],[Section]],3)="ETB","AE3000","") | K24: =_xlfn.IFNA(VLOOKUP(Table5[[#This Row],[Section]],SubSill_Tier,2,FALSE),0) -> 0 | L24: =IFERROR(IF(LEFT(G24,2)="AI",IF(_xlfn.NUMBERVALUE(IFERROR(LEFT(IF(ISERROR(FIND("X",UPPER(B24))),UPPER(B24),RIGHT(UPPER(B24),LEN(UPPER(B24))-FIND("~",SUBSTITUTE(UPPER(B24),"X","~",LEN(UPPER(B24))-LEN(SUBSTITUTE(UPPER(B24),"X","")))))),FIND(" ",IF(ISERROR(FIND("X",UPPER(B24))),UPPER(B24),RIGHT(UPPER(B24),LEN(UPPER(B24))-FIND("~",SUBSTITUTE(UPPER(B24),"X","~",LEN(UPPER(B24))-LEN(SUBSTITUTE(UPPER(B24),"X","")))))),1)-1),IF(ISERROR(FIND("X",UPPER(B24))),UPPER(B24),RIGHT(UPPER(B24),LEN(UPPER(B24))-FIND("~",SUBSTITUTE(UPPER(B24),"X","~",LEN(UPPER(B24))-LEN(SUBSTITUTE(UPPER(B24),"X",""))))))),".")>=5,"Wall",""),""),"") | M24: {=_xlfn.IFS(NOT(ISERROR(VLOOKUP(Table5[[#This Row],[Section]],TB_notTB,1,FALSE))),"No",LEFT(Table5[[#This Row],[Section]],3)="ETB","PLS",LEFT(Table5[[#This Row],[Section]],1)="7","PDB",NOT(ISBLANK(Table5[[#This Row],[Section]])),"No")} -> No | N24: SUNDRY-16 | O24: Sundry description - 16
A25: =N32 -> SUNDRY-24 | B25: =O32 -> Sundry description - 24 | C25: N | D25: 0 | E25: 0 | F25: 0 | G25: =IF(LEFT(Table5[[#This Row],[Section]],3)="ETB","AE3000","") | K25: =_xlfn.IFNA(VLOOKUP(Table5[[#This Row],[Section]],SubSill_Tier,2,FALSE),0) -> 0 | L25: =IFERROR(IF(LEFT(G25,2)="AI",IF(_xlfn.NUMBERVALUE(IFERROR(LEFT(IF(ISERROR(FIND("X",UPPER(B25))),UPPER(B25),RIGHT(UPPER(B25),LEN(UPPER(B25))-FIND("~",SUBSTITUTE(UPPER(B25),"X","~",LEN(UPPER(B25))-LEN(SUBSTITUTE(UPPER(B25),"X","")))))),FIND(" ",IF(ISERROR(FIND("X",UPPER(B25))),UPPER(B25),RIGHT(UPPER(B25),LEN(UPPER(B25))-FIND("~",SUBSTITUTE(UPPER(B25),"X","~",LEN(UPPER(B25))-LEN(SUBSTITUTE(UPPER(B25),"X","")))))),1)-1),IF(ISERROR(FIND("X",UPPER(B25))),UPPER(B25),RIGHT(UPPER(B25),LEN(UPPER(B25))-FIND("~",SUBSTITUTE(UPPER(B25),"X","~",LEN(UPPER(B25))-LEN(SUBSTITUTE(UPPER(B25),"X",""))))))),".")>=5,"Wall",""),""),"") | M25: {=_xlfn.IFS(NOT(ISERROR(VLOOKUP(Table5[[#This Row],[Section]],TB_notTB,1,FALSE))),"No",LEFT(Table5[[#This Row],[Section]],3)="ETB","PLS",LEFT(Table5[[#This Row],[Section]],1)="7","PDB",NOT(ISBLANK(Table5[[#This Row],[Section]])),"No")} -> No | N25: SUNDRY-17 | O25: Sundry description - 17
A26: =N33 -> SUNDRY-25 | B26: =O33 -> Sundry description - 25 | C26: N | D26: 0 | E26: 0 | F26: 0 | G26: =IF(LEFT(Table5[[#This Row],[Section]],3)="ETB","AE3000","") | K26: =_xlfn.IFNA(VLOOKUP(Table5[[#This Row],[Section]],SubSill_Tier,2,FALSE),0) -> 0 | L26: =IFERROR(IF(LEFT(G26,2)="AI",IF(_xlfn.NUMBERVALUE(IFERROR(LEFT(IF(ISERROR(FIND("X",UPPER(B26))),UPPER(B26),RIGHT(UPPER(B26),LEN(UPPER(B26))-FIND("~",SUBSTITUTE(UPPER(B26),"X","~",LEN(UPPER(B26))-LEN(SUBSTITUTE(UPPER(B26),"X","")))))),FIND(" ",IF(ISERROR(FIND("X",UPPER(B26))),UPPER(B26),RIGHT(UPPER(B26),LEN(UPPER(B26))-FIND("~",SUBSTITUTE(UPPER(B26),"X","~",LEN(UPPER(B26))-LEN(SUBSTITUTE(UPPER(B26),"X","")))))),1)-1),IF(ISERROR(FIND("X",UPPER(B26))),UPPER(B26),RIGHT(UPPER(B26),LEN(UPPER(B26))-FIND("~",SUBSTITUTE(UPPER(B26),"X","~",LEN(UPPER(B26))-LEN(SUBSTITUTE(UPPER(B26),"X",""))))))),".")>=5,"Wall",""),""),"") | M26: {=_xlfn.IFS(NOT(ISERROR(VLOOKUP(Table5[[#This Row],[Section]],TB_notTB,1,FALSE))),"No",LEFT(Table5[[#This Row],[Section]],3)="ETB","PLS",LEFT(Table5[[#This Row],[Section]],1)="7","PDB",NOT(ISBLANK(Table5[[#This Row],[Section]])),"No")} -> No | N26: SUNDRY-18 | O26: Sundry description - 18
A27: =N34 -> SUNDRY-26 | B27: =O34 -> Sundry description - 26 | C27: N | D27: 0 | E27: 0 | F27: 0 | G27: =IF(LEFT(Table5[[#This Row],[Section]],3)="ETB","AE3000","") | K27: =_xlfn.IFNA(VLOOKUP(Table5[[#This Row],[Section]],SubSill_Tier,2,FALSE),0) -> 0 | L27: =IFERROR(IF(LEFT(G27,2)="AI",IF(_xlfn.NUMBERVALUE(IFERROR(LEFT(IF(ISERROR(FIND("X",UPPER(B27))),UPPER(B27),RIGHT(UPPER(B27),LEN(UPPER(B27))-FIND("~",SUBSTITUTE(UPPER(B27),"X","~",LEN(UPPER(B27))-LEN(SUBSTITUTE(UPPER(B27),"X","")))))),FIND(" ",IF(ISERROR(FIND("X",UPPER(B27))),UPPER(B27),RIGHT(UPPER(B27),LEN(UPPER(B27))-FIND("~",SUBSTITUTE(UPPER(B27),"X","~",LEN(UPPER(B27))-LEN(SUBSTITUTE(UPPER(B27),"X","")))))),1)-1),IF(ISERROR(FIND("X",UPPER(B27))),UPPER(B27),RIGHT(UPPER(B27),LEN(UPPER(B27))-FIND("~",SUBSTITUTE(UPPER(B27),"X","~",LEN(UPPER(B27))-LEN(SUBSTITUTE(UPPER(B27),"X",""))))))),".")>=5,"Wall",""),""),"") | M27: {=_xlfn.IFS(NOT(ISERROR(VLOOKUP(Table5[[#This Row],[Section]],TB_notTB,1,FALSE))),"No",LEFT(Table5[[#This Row],[Section]],3)="ETB","PLS",LEFT(Table5[[#This Row],[Section]],1)="7","PDB",NOT(ISBLANK(Table5[[#This Row],[Section]])),"No")} -> No | N27: SUNDRY-19 | O27: Sundry description - 19
A28: =N35 -> SUNDRY-27 | B28: =O35 -> Sundry description - 27 | C28: N | D28: 0 | E28: 0 | F28: 0 | G28: =IF(LEFT(Table5[[#This Row],[Section]],3)="ETB","AE3000","") | K28: =_xlfn.IFNA(VLOOKUP(Table5[[#This Row],[Section]],SubSill_Tier,2,FALSE),0) -> 0 | L28: =IFERROR(IF(LEFT(G28,2)="AI",IF(_xlfn.NUMBERVALUE(IFERROR(LEFT(IF(ISERROR(FIND("X",UPPER(B28))),UPPER(B28),RIGHT(UPPER(B28),LEN(UPPER(B28))-FIND("~",SUBSTITUTE(UPPER(B28),"X","~",LEN(UPPER(B28))-LEN(SUBSTITUTE(UPPER(B28),"X","")))))),FIND(" ",IF(ISERROR(FIND("X",UPPER(B28))),UPPER(B28),RIGHT(UPPER(B28),LEN(UPPER(B28))-FIND("~",SUBSTITUTE(UPPER(B28),"X","~",LEN(UPPER(B28))-LEN(SUBSTITUTE(UPPER(B28),"X","")))))),1)-1),IF(ISERROR(FIND("X",UPPER(B28))),UPPER(B28),RIGHT(UPPER(B28),LEN(UPPER(B28))-FIND("~",SUBSTITUTE(UPPER(B28),"X","~",LEN(UPPER(B28))-LEN(SUBSTITUTE(UPPER(B28),"X",""))))))),".")>=5,"Wall",""),""),"") | M28: {=_xlfn.IFS(NOT(ISERROR(VLOOKUP(Table5[[#This Row],[Section]],TB_notTB,1,FALSE))),"No",LEFT(Table5[[#This Row],[Section]],3)="ETB","PLS",LEFT(Table5[[#This Row],[Section]],1)="7","PDB",NOT(ISBLANK(Table5[[#This Row],[Section]])),"No")} -> No | N28: SUNDRY-20 | O28: Sundry description - 20
A29: =N36 -> SUNDRY-28 | B29: =O36 -> Sundry description - 28 | C29: N | D29: 0 | E29: 0 | F29: 0 | G29: =IF(LEFT(Table5[[#This Row],[Section]],3)="ETB","AE3000","") | K29: =_xlfn.IFNA(VLOOKUP(Table5[[#This Row],[Section]],SubSill_Tier,2,FALSE),0) -> 0 | L29: =IFERROR(IF(LEFT(G29,2)="AI",IF(_xlfn.NUMBERVALUE(IFERROR(LEFT(IF(ISERROR(FIND("X",UPPER(B29))),UPPER(B29),RIGHT(UPPER(B29),LEN(UPPER(B29))-FIND("~",SUBSTITUTE(UPPER(B29),"X","~",LEN(UPPER(B29))-LEN(SUBSTITUTE(UPPER(B29),"X","")))))),FIND(" ",IF(ISERROR(FIND("X",UPPER(B29))),UPPER(B29),RIGHT(UPPER(B29),LEN(UPPER(B29))-FIND("~",SUBSTITUTE(UPPER(B29),"X","~",LEN(UPPER(B29))-LEN(SUBSTITUTE(UPPER(B29),"X","")))))),1)-1),IF(ISERROR(FIND("X",UPPER(B29))),UPPER(B29),RIGHT(UPPER(B29),LEN(UPPER(B29))-FIND("~",SUBSTITUTE(UPPER(B29),"X","~",LEN(UPPER(B29))-LEN(SUBSTITUTE(UPPER(B29),"X",""))))))),".")>=5,"Wall",""),""),"") | M29: {=_xlfn.IFS(NOT(ISERROR(VLOOKUP(Table5[[#This Row],[Section]],TB_notTB,1,FALSE))),"No",LEFT(Table5[[#This Row],[Section]],3)="ETB","PLS",LEFT(Table5[[#This Row],[Section]],1)="7","PDB",NOT(ISBLANK(Table5[[#This Row],[Section]])),"No")} -> No | N29: SUNDRY-21 | O29: Sundry description - 21
A30: =N37 -> SUNDRY-29 | B30: =O37 -> Sundry description - 29 | C30: N | D30: 0 | E30: 0 | F30: 0 | G30: =IF(LEFT(Table5[[#This Row],[Section]],3)="ETB","AE3000","") | K30: =_xlfn.IFNA(VLOOKUP(Table5[[#This Row],[Section]],SubSill_Tier,2,FALSE),0) -> 0 | L30: =IFERROR(IF(LEFT(G30,2)="AI",IF(_xlfn.NUMBERVALUE(IFERROR(LEFT(IF(ISERROR(FIND("X",UPPER(B30))),UPPER(B30),RIGHT(UPPER(B30),LEN(UPPER(B30))-FIND("~",SUBSTITUTE(UPPER(B30),"X","~",LEN(UPPER(B30))-LEN(SUBSTITUTE(UPPER(B30),"X","")))))),FIND(" ",IF(ISERROR(FIND("X",UPPER(B30))),UPPER(B30),RIGHT(UPPER(B30),LEN(UPPER(B30))-FIND("~",SUBSTITUTE(UPPER(B30),"X","~",LEN(UPPER(B30))-LEN(SUBSTITUTE(UPPER(B30),"X","")))))),1)-1),IF(ISERROR(FIND("X",UPPER(B30))),UPPER(B30),RIGHT(UPPER(B30),LEN(UPPER(B30))-FIND("~",SUBSTITUTE(UPPER(B30),"X","~",LEN(UPPER(B30))-LEN(SUBSTITUTE(UPPER(B30),"X",""))))))),".")>=5,"Wall",""),""),"") | M30: {=_xlfn.IFS(NOT(ISERROR(VLOOKUP(Table5[[#This Row],[Section]],TB_notTB,1,FALSE))),"No",LEFT(Table5[[#This Row],[Section]],3)="ETB","PLS",LEFT(Table5[[#This Row],[Section]],1)="7","PDB",NOT(ISBLANK(Table5[[#This Row],[Section]])),"No")} -> No | N30: SUNDRY-22 | O30: Sundry description - 22
A31: =N38 -> SUNDRY-30 | B31: =O38 -> Sundry description - 30 | C31: N | D31: 0 | E31: 0 | F31: 0 | G31: =IF(LEFT(Table5[[#This Row],[Section]],3)="ETB","AE3000","") | K31: =_xlfn.IFNA(VLOOKUP(Table5[[#This Row],[Section]],SubSill_Tier,2,FALSE),0) -> 0 | L31: =IFERROR(IF(LEFT(G31,2)="AI",IF(_xlfn.NUMBERVALUE(IFERROR(LEFT(IF(ISERROR(FIND("X",UPPER(B31))),UPPER(B31),RIGHT(UPPER(B31),LEN(UPPER(B31))-FIND("~",SUBSTITUTE(UPPER(B31),"X","~",LEN(UPPER(B31))-LEN(SUBSTITUTE(UPPER(B31),"X","")))))),FIND(" ",IF(ISERROR(FIND("X",UPPER(B31))),UPPER(B31),RIGHT(UPPER(B31),LEN(UPPER(B31))-FIND("~",SUBSTITUTE(UPPER(B31),"X","~",LEN(UPPER(B31))-LEN(SUBSTITUTE(UPPER(B31),"X","")))))),1)-1),IF(ISERROR(FIND("X",UPPER(B31))),UPPER(B31),RIGHT(UPPER(B31),LEN(UPPER(B31))-FIND("~",SUBSTITUTE(UPPER(B31),"X","~",LEN(UPPER(B31))-LEN(SUBSTITUTE(UPPER(B31),"X",""))))))),".")>=5,"Wall",""),""),"") | M31: {=_xlfn.IFS(NOT(ISERROR(VLOOKUP(Table5[[#This Row],[Section]],TB_notTB,1,FALSE))),"No",LEFT(Table5[[#This Row],[Section]],3)="ETB","PLS",LEFT(Table5[[#This Row],[Section]],1)="7","PDB",NOT(ISBLANK(Table5[[#This Row],[Section]])),"No")} -> No | N31: SUNDRY-23 | O31: Sundry description - 23
A32: =N39 -> SUNDRY-31 | B32: =O39 -> Sundry description - 31 | C32: N | D32: 0 | E32: 0 | F32: 0 | G32: =IF(LEFT(Table5[[#This Row],[Section]],3)="ETB","AE3000","") | K32: =_xlfn.IFNA(VLOOKUP(Table5[[#This Row],[Section]],SubSill_Tier,2,FALSE),0) -> 0 | L32: =IFERROR(IF(LEFT(G32,2)="AI",IF(_xlfn.NUMBERVALUE(IFERROR(LEFT(IF(ISERROR(FIND("X",UPPER(B32))),UPPER(B32),RIGHT(UPPER(B32),LEN(UPPER(B32))-FIND("~",SUBSTITUTE(UPPER(B32),"X","~",LEN(UPPER(B32))-LEN(SUBSTITUTE(UPPER(B32),"X","")))))),FIND(" ",IF(ISERROR(FIND("X",UPPER(B32))),UPPER(B32),RIGHT(UPPER(B32),LEN(UPPER(B32))-FIND("~",SUBSTITUTE(UPPER(B32),"X","~",LEN(UPPER(B32))-LEN(SUBSTITUTE(UPPER(B32),"X","")))))),1)-1),IF(ISERROR(FIND("X",UPPER(B32))),UPPER(B32),RIGHT(UPPER(B32),LEN(UPPER(B32))-FIND("~",SUBSTITUTE(UPPER(B32),"X","~",LEN(UPPER(B32))-LEN(SUBSTITUTE(UPPER(B32),"X",""))))))),".")>=5,"Wall",""),""),"") | M32: {=_xlfn.IFS(NOT(ISERROR(VLOOKUP(Table5[[#This Row],[Section]],TB_notTB,1,FALSE))),"No",LEFT(Table5[[#This Row],[Section]],3)="ETB","PLS",LEFT(Table5[[#This Row],[Section]],1)="7","PDB",NOT(ISBLANK(Table5[[#This Row],[Section]])),"No")} -> No | N32: SUNDRY-24 | O32: Sundry description - 24
A33: =N40 -> SUNDRY-32 | B33: =O40 -> Sundry description - 32 | C33: N | D33: 0 | E33: 0 | F33: 0 | G33: =IF(LEFT(Table5[[#This Row],[Section]],3)="ETB","AE3000","") | K33: =_xlfn.IFNA(VLOOKUP(Table5[[#This Row],[Section]],SubSill_Tier,2,FALSE),0) -> 0 | L33: =IFERROR(IF(LEFT(G33,2)="AI",IF(_xlfn.NUMBERVALUE(IFERROR(LEFT(IF(ISERROR(FIND("X",UPPER(B33))),UPPER(B33),RIGHT(UPPER(B33),LEN(UPPER(B33))-FIND("~",SUBSTITUTE(UPPER(B33),"X","~",LEN(UPPER(B33))-LEN(SUBSTITUTE(UPPER(B33),"X","")))))),FIND(" ",IF(ISERROR(FIND("X",UPPER(B33))),UPPER(B33),RIGHT(UPPER(B33),LEN(UPPER(B33))-FIND("~",SUBSTITUTE(UPPER(B33),"X","~",LEN(UPPER(B33))-LEN(SUBSTITUTE(UPPER(B33),"X","")))))),1)-1),IF(ISERROR(FIND("X",UPPER(B33))),UPPER(B33),RIGHT(UPPER(B33),LEN(UPPER(B33))-FIND("~",SUBSTITUTE(UPPER(B33),"X","~",LEN(UPPER(B33))-LEN(SUBSTITUTE(UPPER(B33),"X",""))))))),".")>=5,"Wall",""),""),"") | M33: {=_xlfn.IFS(NOT(ISERROR(VLOOKUP(Table5[[#This Row],[Section]],TB_notTB,1,FALSE))),"No",LEFT(Table5[[#This Row],[Section]],3)="ETB","PLS",LEFT(Table5[[#This Row],[Section]],1)="7","PDB",NOT(ISBLANK(Table5[[#This Row],[Section]])),"No")} -> No | N33: SUNDRY-25 | O33: Sundry description - 25
... A76: =N83 -> SUNDRY-75 | B76: =O83 -> Sundry description - 75 | C76: N | D76: 0 | E76: 0 | F76: 0 | G76: =IF(LEFT(Table5[[#This Row],[Section]],3)="ETB","AE3000","") | K76: =_xlfn.IFNA(VLOOKUP(Table5[[#This Row],[Section]],SubSill_Tier,2,FALSE),0) -> 0 | L76: =IFERROR(IF(LEFT(G76,2)="AI",IF(_xlfn.NUMBERVALUE(IFERROR(LEFT(IF(ISERROR(FIND("X",UPPER(B76))),UPPER(B76),RIGHT(UPPER(B76),LEN(UPPER(B76))-FIND("~",SUBSTITUTE(UPPER(B76),"X","~",LEN(UPPER(B76))-LEN(SUBSTITUTE(UPPER(B76),"X","")))))),FIND(" ",IF(ISERROR(FIND("X",UPPER(B76))),UPPER(B76),RIGHT(UPPER(B76),LEN(UPPER(B76))-FIND("~",SUBSTITUTE(UPPER(B76),"X","~",LEN(UPPER(B76))-LEN(SUBSTITUTE(UPPER(B76),"X","")))))),1)-1),IF(ISERROR(FIND("X",UPPER(B76))),UPPER(B76),RIGHT(UPPER(B76),LEN(UPPER(B76))-FIND("~",SUBSTITUTE(UPPER(B76),"X","~",LEN(UPPER(B76))-LEN(SUBSTITUTE(UPPER(B76),"X",""))))))),".")>=5,"Wall",""),""),"") | M76: {=_xlfn.IFS(NOT(ISERROR(VLOOKUP(Table5[[#This Row],[Section]],TB_notTB,1,FALSE))),"No",LEFT(Table5[[#This Row],[Section]],3)="ETB","PLS",LEFT(Table5[[#This Row],[Section]],1)="7","PDB",NOT(ISBLANK(Table5[[#This Row],[Section]])),"No")} -> No | N76: SUNDRY-68 | O76: Sundry description - 68
A77: 735663 | B77: C9367U U-MAX 66MM RAIL | C77: N | D77: 1.147 | E77: 428 | F77: 428 | G77: AE3615 | H77: 100012122131221014 | I77: EDGE MAX Sliding Door Single & DG | J77: BU | K77: =_xlfn.IFNA(VLOOKUP(Table5[[#This Row],[Section]],SubSill_Tier,2,FALSE),0) -> 0 | L77: =IFERROR(IF(LEFT(G77,2)="AI",IF(_xlfn.NUMBERVALUE(IFERROR(LEFT(IF(ISERROR(FIND("X",UPPER(B77))),UPPER(B77),RIGHT(UPPER(B77),LEN(UPPER(B77))-FIND("~",SUBSTITUTE(UPPER(B77),"X","~",LEN(UPPER(B77))-LEN(SUBSTITUTE(UPPER(B77),"X","")))))),FIND(" ",IF(ISERROR(FIND("X",UPPER(B77))),UPPER(B77),RIGHT(UPPER(B77),LEN(UPPER(B77))-FIND("~",SUBSTITUTE(UPPER(B77),"X","~",LEN(UPPER(B77))-LEN(SUBSTITUTE(UPPER(B77),"X","")))))),1)-1),IF(ISERROR(FIND("X",UPPER(B77))),UPPER(B77),RIGHT(UPPER(B77),LEN(UPPER(B77))-FIND("~",SUBSTITUTE(UPPER(B77),"X","~",LEN(UPPER(B77))-LEN(SUBSTITUTE(UPPER(B77),"X",""))))))),".")>=5,"Wall",""),""),"") | M77: {=_xlfn.IFS(NOT(ISERROR(VLOOKUP(Table5[[#This Row],[Section]],TB_notTB,1,FALSE))),"No",LEFT(Table5[[#This Row],[Section]],3)="ETB","PLS",LEFT(Table5[[#This Row],[Section]],1)="7","PDB",NOT(ISBLANK(Table5[[#This Row],[Section]])),"No")} -> PDB | N77: SUNDRY-69 | O77: Sundry description - 69
A78: 735664 | B78: C9367U U-MAX 66MM RAIL | C78: N | D78: 1.147 | E78: 428 | F78: 428 | G78: AE3615 | H78: 100012122131221014 | I78: EDGE MAX Sliding Door Single & DG | J78: BU | K78: =_xlfn.IFNA(VLOOKUP(Table5[[#This Row],[Section]],SubSill_Tier,2,FALSE),0) -> 0 | L78: =IFERROR(IF(LEFT(G78,2)="AI",IF(_xlfn.NUMBERVALUE(IFERROR(LEFT(IF(ISERROR(FIND("X",UPPER(B78))),UPPER(B78),RIGHT(UPPER(B78),LEN(UPPER(B78))-FIND("~",SUBSTITUTE(UPPER(B78),"X","~",LEN(UPPER(B78))-LEN(SUBSTITUTE(UPPER(B78),"X","")))))),FIND(" ",IF(ISERROR(FIND("X",UPPER(B78))),UPPER(B78),RIGHT(UPPER(B78),LEN(UPPER(B78))-FIND("~",SUBSTITUTE(UPPER(B78),"X","~",LEN(UPPER(B78))-LEN(SUBSTITUTE(UPPER(B78),"X","")))))),1)-1),IF(ISERROR(FIND("X",UPPER(B78))),UPPER(B78),RIGHT(UPPER(B78),LEN(UPPER(B78))-FIND("~",SUBSTITUTE(UPPER(B78),"X","~",LEN(UPPER(B78))-LEN(SUBSTITUTE(UPPER(B78),"X",""))))))),".")>=5,"Wall",""),""),"") | M78: {=_xlfn.IFS(NOT(ISERROR(VLOOKUP(Table5[[#This Row],[Section]],TB_notTB,1,FALSE))),"No",LEFT(Table5[[#This Row],[Section]],3)="ETB","PLS",LEFT(Table5[[#This Row],[Section]],1)="7","PDB",NOT(ISBLANK(Table5[[#This Row],[Section]])),"No")} -> PDB | N78: SUNDRY-70 | O78: Sundry description - 70
A79: 735665 | B79: C5308U U-MAX 150 SPANDREL INFIL SUBSILL-SLOT | C79: N | D79: 2.323 | E79: 807 | F79: 807 | G79: AE3695 | H79: 100012122331223001 | I79: EDGE 150mm Sub Framing | J79: BU | K79: =_xlfn.IFNA(VLOOKUP(Table5[[#This Row],[Section]],SubSill_Tier,2,FALSE),0) -> 0 | L79: =IFERROR(IF(LEFT(G79,2)="AI",IF(_xlfn.NUMBERVALUE(IFERROR(LEFT(IF(ISERROR(FIND("X",UPPER(B79))),UPPER(B79),RIGHT(UPPER(B79),LEN(UPPER(B79))-FIND("~",SUBSTITUTE(UPPER(B79),"X","~",LEN(UPPER(B79))-LEN(SUBSTITUTE(UPPER(B79),"X","")))))),FIND(" ",IF(ISERROR(FIND("X",UPPER(B79))),UPPER(B79),RIGHT(UPPER(B79),LEN(UPPER(B79))-FIND("~",SUBSTITUTE(UPPER(B79),"X","~",LEN(UPPER(B79))-LEN(SUBSTITUTE(UPPER(B79),"X","")))))),1)-1),IF(ISERROR(FIND("X",UPPER(B79))),UPPER(B79),RIGHT(UPPER(B79),LEN(UPPER(B79))-FIND("~",SUBSTITUTE(UPPER(B79),"X","~",LEN(UPPER(B79))-LEN(SUBSTITUTE(UPPER(B79),"X",""))))))),".")>=5,"Wall",""),""),"") | M79: {=_xlfn.IFS(NOT(ISERROR(VLOOKUP(Table5[[#This Row],[Section]],TB_notTB,1,FALSE))),"No",LEFT(Table5[[#This Row],[Section]],3)="ETB","PLS",LEFT(Table5[[#This Row],[Section]],1)="7","PDB",NOT(ISBLANK(Table5[[#This Row],[Section]])),"No")} -> PDB | N79: SUNDRY-71 | O79: Sundry description - 71
A80: 735666 | B80: C5308U U-MAX 150 SPANDREL INFIL SUBSILL-SLOT | C80: N | D80: 2.323 | E80: 807 | F80: 807 | G80: AE3695 | H80: 100012122331223001 | I80: EDGE 150mm Sub Framing | J80: BU | K80: =_xlfn.IFNA(VLOOKUP(Table5[[#This Row],[Section]],SubSill_Tier,2,FALSE),0) -> 0 | L80: =IFERROR(IF(LEFT(G80,2)="AI",IF(_xlfn.NUMBERVALUE(IFERROR(LEFT(IF(ISERROR(FIND("X",UPPER(B80))),UPPER(B80),RIGHT(UPPER(B80),LEN(UPPER(B80))-FIND("~",SUBSTITUTE(UPPER(B80),"X","~",LEN(UPPER(B80))-LEN(SUBSTITUTE(UPPER(B80),"X","")))))),FIND(" ",IF(ISERROR(FIND("X",UPPER(B80))),UPPER(B80),RIGHT(UPPER(B80),LEN(UPPER(B80))-FIND("~",SUBSTITUTE(UPPER(B80),"X","~",LEN(UPPER(B80))-LEN(SUBSTITUTE(UPPER(B80),"X","")))))),1)-1),IF(ISERROR(FIND("X",UPPER(B80))),UPPER(B80),RIGHT(UPPER(B80),LEN(UPPER(B80))-FIND("~",SUBSTITUTE(UPPER(B80),"X","~",LEN(UPPER(B80))-LEN(SUBSTITUTE(UPPER(B80),"X",""))))))),".")>=5,"Wall",""),""),"") | M80: {=_xlfn.IFS(NOT(ISERROR(VLOOKUP(Table5[[#This Row],[Section]],TB_notTB,1,FALSE))),"No",LEFT(Table5[[#This Row],[Section]],3)="ETB","PLS",LEFT(Table5[[#This Row],[Section]],1)="7","PDB",NOT(ISBLANK(Table5[[#This Row],[Section]])),"No")} -> PDB | N80: SUNDRY-72 | O80: Sundry description - 72
A81: 735667 | B81: C5310U U-MAX 150 SPANDREL SUBHEAD | C81: N | D81: 2.435 | E81: 729 | F81: 729 | G81: AE3695 | H81: 100012122331223001 | I81: EDGE 150mm Sub Framing | J81: BU | K81: =_xlfn.IFNA(VLOOKUP(Table5[[#This Row],[Section]],SubSill_Tier,2,FALSE),0) -> 0 | L81: =IFERROR(IF(LEFT(G81,2)="AI",IF(_xlfn.NUMBERVALUE(IFERROR(LEFT(IF(ISERROR(FIND("X",UPPER(B81))),UPPER(B81),RIGHT(UPPER(B81),LEN(UPPER(B81))-FIND("~",SUBSTITUTE(UPPER(B81),"X","~",LEN(UPPER(B81))-LEN(SUBSTITUTE(UPPER(B81),"X","")))))),FIND(" ",IF(ISERROR(FIND("X",UPPER(B81))),UPPER(B81),RIGHT(UPPER(B81),LEN(UPPER(B81))-FIND("~",SUBSTITUTE(UPPER(B81),"X","~",LEN(UPPER(B81))-LEN(SUBSTITUTE(UPPER(B81),"X","")))))),1)-1),IF(ISERROR(FIND("X",UPPER(B81))),UPPER(B81),RIGHT(UPPER(B81),LEN(UPPER(B81))-FIND("~",SUBSTITUTE(UPPER(B81),"X","~",LEN(UPPER(B81))-LEN(SUBSTITUTE(UPPER(B81),"X",""))))))),".")>=5,"Wall",""),""),"") | M81: {=_xlfn.IFS(NOT(ISERROR(VLOOKUP(Table5[[#This Row],[Section]],TB_notTB,1,FALSE))),"No",LEFT(Table5[[#This Row],[Section]],3)="ETB","PLS",LEFT(Table5[[#This Row],[Section]],1)="7","PDB",NOT(ISBLANK(Table5[[#This Row],[Section]])),"No")} -> PDB | N81: SUNDRY-73 | O81: Sundry description - 73
A82: 735668 | B82: C5312U U-MAX 150 ODG HD SHALLOW MULLION | C82: N | D82: 2.499 | E82: 763 | F82: 763 | G82: AE3580 | H82: 100012122131221007 | I82: EDGE MAX 150 Offset DG 34mm P | J82: BU | K82: =_xlfn.IFNA(VLOOKUP(Table5[[#This Row],[Section]],SubSill_Tier,2,FALSE),0) -> 0 | L82: =IFERROR(IF(LEFT(G82,2)="AI",IF(_xlfn.NUMBERVALUE(IFERROR(LEFT(IF(ISERROR(FIND("X",UPPER(B82))),UPPER(B82),RIGHT(UPPER(B82),LEN(UPPER(B82))-FIND("~",SUBSTITUTE(UPPER(B82),"X","~",LEN(UPPER(B82))-LEN(SUBSTITUTE(UPPER(B82),"X","")))))),FIND(" ",IF(ISERROR(FIND("X",UPPER(B82))),UPPER(B82),RIGHT(UPPER(B82),LEN(UPPER(B82))-FIND("~",SUBSTITUTE(UPPER(B82),"X","~",LEN(UPPER(B82))-LEN(SUBSTITUTE(UPPER(B82),"X","")))))),1)-1),IF(ISERROR(FIND("X",UPPER(B82))),UPPER(B82),RIGHT(UPPER(B82),LEN(UPPER(B82))-FIND("~",SUBSTITUTE(UPPER(B82),"X","~",LEN(UPPER(B82))-LEN(SUBSTITUTE(UPPER(B82),"X",""))))))),".")>=5,"Wall",""),""),"") | M82: {=_xlfn.IFS(NOT(ISERROR(VLOOKUP(Table5[[#This Row],[Section]],TB_notTB,1,FALSE))),"No",LEFT(Table5[[#This Row],[Section]],3)="ETB","PLS",LEFT(Table5[[#This Row],[Section]],1)="7","PDB",NOT(ISBLANK(Table5[[#This Row],[Section]])),"No")} -> PDB | N82: SUNDRY-74 | O82: Sundry description - 74
...

Sheet DATA_EDGE
A1: Mat.Ref.No | B1: Mat.Ref.Description | C1: SAP.Mat.No | E1: Reverse sort to ensure sections are at top
A2: C001 | B2: C001 Wide Wiper Stile | C2: EP23000 | E2: This should make TB items select the ETB code rather than the 7 code
A3: C002 | B3: C002 Wide Hinge Stile | C3: EP23001
A4: C003 | B4: C003 Wide Lock Stile | C4: EP23002
A5: C004 | B5: C004 Wide Pivot Stile | C5: EP23003
A6: C0054 | B6: C0054 Overlap Sash Bead | C6: EP23004
A7: C015 | B7: C015 Glazing Base to suit C016 | C7: EP23005
A8: C016 | B8: C016 Glazing Bead to suit C015 | C8: EP23006
A9: C016-2 | B9: C016-2 Overlap Sash Bead | C9: EP23007
A10: C017 | B10: C017 Glazing Channel 18mm Pocket | C10: EP23008
A11: C0256 | B11: C0256 Hand Rail | C11: EP23009
A12: C0385 | B12: C0385 150 Sub Sill Slotted 5mm Setback | C12: EP23010
A13: C0390 | B13: C0390 45mm Door Spiggot | C13: EP23011
A14: C046 | B14: C046 Beaded Lock Stile | C14: EP23012
... A1191: C9978 | B1191: C9978 Max Hd Meeting Stile | C1191: EP23741

Sheet Validation
A1: Market Segment | B1: Product Segment | C1: Region | E1: LocAl Logo Options | G1: Sundry Type | J1: TB Pricing | K1: Subsills (slotting) | L1: Tier | N1: Thresholds | P1: TB but not TB | R1: PC Applicator | S1: Custom? | T1: AP or PP | U1: Groups (1=Capral,2=Other) | V1: Ano Applicator | W1: Finish Mill | X1: PC Groups Capral | Z1: PC Groups Other | AA1: Custom? | AB1: Ano Groups Capral | AD1: Ano Groups Other
A2: Private Residential - Detached | B2: Commercial | C2: NQ | E2: None | G2: Each length | J2: List less Discount | K2: E27281 | L2: 1 | N2: EP2366 | P2: ETB0003 | R2: n/a | S2: 0 | T2: 0 | U2: 2 | V2: n/a | W2: n/a | X2: Group 1 | Y2: -> | Z2: Group 1 | AA2: 0 | AB2: 20um Clear | AC2: -> | AD2: 20um Clear
A3: Private Residential - Other | B3: Residential | C3: NSW | E3: LocAl Green | G3: Section total | J3: Margin | K3: E18673 | L3: 1 | N3: EP5796 | P3: ETB0007 | R3: Capral P&P - Bremer (AP) | S3: 0 | T3: 0 | U3: 1 | V3: Capral/AAF QLD anodising | X3: Group 2 | Y3: -> | Z3: Group 2 | AA3: 0 | AB3: 25um Clear | AC3: -> | AD3: 25um Clear
A4: Public Dwelling | B4: Security | C4: NT | E4: LocAl SuperGreen | K4: E30786 | L4: 1 | N4: EP15939 | P4: ETB0008 | R4: Capral P&P - Campbellfield (AP) | S4: 0 | T4: 0 | U4: 1 | V4: WA Anodisers | X4: Group 3 | Y4: -> | Z4: Group 3 | AA4: 0 | AB4: Group POA | AC4: -> | AD4: Group POA
A5: Office | B5: Industrial | C5: SA | K5: E32266 | L5: 1 | N5: E35737 | P5: ETB0009 | R5: Capral P&P - Canningvale (PP) | S5: 0 | T5: 1 | U5: 1 | V5: Other - pls check pricing | X5: Group 4 | Y5: -> | Z5: Group POA | AA5: 0 | AB5: not implemented - review when anodiing groups updated
A6: Retail | B6: Shower & Robe | C6: SEQ | K6: E32359 | L6: 1 | N6: EP2212 | P6: ETB0205 | R6: Capral P&P - HWood Non-Bulk (AP) | S6: 0 | T6: 0 | U6: 1 | X6: Group 5 | Y6: -> | Z6: Group POA | AA6: 0
A7: Hotel | C7: TAS | K7: E32370 | L7: 1 | N7: EP2365 | P7: ETB0207 | R7: Capral P&P - HWood Bulk (AP) | S7: 0 | T7: 0 | U7: 1 | X7: Group POA | Y7: -> | Z7: Group POA | AA7: 1
A8: Factory | C8: VIC | E8: Anodised Thresholds | K8: E35590 | L8: 1 | N8: EP20049 | P8: ETB0217 | R8: Capral Mill (AP) | S8: 4 | T8: 0 | U8: 1
A9: Warehouse | C9: WA | E9: No | K9: E52619 | L9: 1 | N9: EP13539 | P9: ETB0344 | R9: AAF powdercoat | S9: 0 | T9: 0 | U9: 2
A10: Education | E10: 20um Clear | F10: 3A | K10: EA2924 | L10: 1 | N10: EP13540 | R10: Powderline WA | S10: 0 | T10: 1 | U10: 2
A11: Health | E11: 25um Clear | F11: 4A | K11: EAL11812 | L11: 1 | N11: EP22082 | R11: Other - pls check pricing | S11: 1 | T11: 2 | U11: 2
A12: Entertainment/Recreation | K12: ED7908 | L12: 1 | N12: EP22083 | W12: Yes No | X12: No
A13: Other | K13: ED7991 | L13: 1 | N13: E01854 | W13: Yes | X13: No
K14: ED8536 | L14: 1 | N14: EP20050 | R14: PC Price 1 (pp/ap) | S14: Finish Type | T14: Powder Supplier | W14: No
H15: Alloy Extras | K15: ED8597 | L15: 1 | R15: Anodised Perimeter (AP) | S15: Mill Finish | T15: n/a
H16: 6060 | K16: ED8654 | L16: 1 | R16: Paint Perimeter (PP) | S16: Anodised | T16: Interpon
H17: 6063 | K17: EL4088 | L17: 1 | S17: Powder | T17: Dulux
H18: 6106 | K18: EL5181 | L18: 1 | R18: PC Price 2 (ap only)
H19: 6101 | K19: EL5182 | L19: 1 | R19: Anodised Perimeter (AP)
H20: 1350 | K20: EME10009 | L20: 1
H21: 6005A | K21: EME10015 | L21: 1 | R21: PC Price 3 (PP only)
H22: 6082 | K22: EME10389 | L22: 1 | R22: Paint Perimeter (PP)
H23: 6351 | K23: EME31569 | L23: 1
H24: 6061 | K24: EN5202 | L24: 1 | R24: PC Price 4 (MF)
K25: EN5328 | L25: 1 | R25: n/a
B26: NSW | C26: 15 Huntingwood Drive | D26: Huntingwood, NSW, 2148 | H26: Temper Extras | K26: EN5980 | L26: 1
B27: SEQ | C27: 71 Ashburn Road, Bundamba QLD 4304 | D27: PO Box 768, Booval Fair QLD 4304 | H27: T1 | K27: EN6523 | L27: 1
B28: NQ | C28: 303 Woolcock St, Garbutt QLD 4814 | D28: PO Box 7385, Garbutt QLD 4814 | H28: T4 | K28: EN6524 | L28: 1 | R28: Type | S28: Applicator | T28: Result
B29: NT | C29: 8 Mataram Street, Winnellie NT 0820 | D29: PO Box 38296, Winnellie NT 0820 | H29: T5 | K29: EP10573 | L29: 1 | R29: Mill Finish | S29: n/a | T29: n/a
B30: SA | C30: 70 Grand Junction Road | D30: Kilburn SA 5084 | H30: T6 | K30: EP11442 | L30: 1 | R30: Anodised | S30: Anodiser TBC | T30: Anodised Perimeter (AP)
B31: TAS | C31: 116 Grove Road | D31: PO Box 1177 | E31: Glenorchy TAS 7010 | H31: T591 | K31: EP11928 | L31: 1 | R31: Anodised | S31: Capral/AAF QLD anodising | T31: Anodised Perimeter (AP)
B32: VIC | C32: 151 Barry Road, Campbellfield VIC 3061 | D32: PO Box 68, Cambellfield VIC 3061 | H32: T595 | K32: EP12062 | L32: 1 | R32: Anodised | S32: WA Anodisers | T32: Anodised Perimeter (AP)
B33: WA | C33: 45 - 55 Baile Road | D33: Canning Vale WA 6155 | E33: or 2 Competition Way | F33: Wangara WA 6065 | H33: T52 | K33: EP12101 | L33: 1 | R33: Anodised | S33: Ano Other - pls check pricing | T33: Anodised Perimeter (AP)
K34: EP1285 | L34: 1 | R34: Powder | S34: Powdercoater TBC | T34: Anodised Perimeter (AP)
K35: EP12896 | L35: 1 | R35: Powder | S35: Capral | T35: Anodised Perimeter (AP)
K36: EP13090 | L36: 1 | R36: Powder | S36: AAF powdercoat | T36: Anodised Perimeter (AP)
K37: EP13091 | L37: 1 | R37: Powder | S37: Powderline WA | T37: Paint Perimeter (PP)
K38: EP13388 | L38: 1 | R38: Powder | S38: PC Other - pls check pricing | T38: Anodised Perimeter (AP)
K39: EP14149 | L39: 1
K40: EP14579 | L40: 1
...

Sheet Pricing Matrix
J1: COSTS - UPDATED MONTHLY (as per Mill pricing agreement) | AG1: From MM60 (moving average cost stock on floor) Use 3010 as will be most active AE3000 to AE3999, AR2015, AR2025, AR2045, AR1245
A2: Metal Pricing | E2: PDB Metal Costing | H2: Standard delivery charge | J2: What | K2: Value | L2: Notes | S2: Thermal Break Costs | AB2: =tb_calc_type -> Margin | AC2: =tb_calc_value -> 0.5 | AH2: 46174 | AI2: 46083 | AJ2: 45840 | AK2: 45749 | AL2: 45628 | AM2: 45460 | AN2: 45313 | AO2: 45076 | AQ2: prior to 02/05/2022 | AR2: 44473 | AS2: 43886 | AT2: 43556
A3: LME + billet premium | B3: =Table_Costs[[#This Row],[Value]] -> 5.61 | C3: 46174 | D3: =TEXT(DAY(C3),"00") -> 01 | E3: Extra Spread | F3: 0.35 | G3: $/kg | H3: 97 | J3: LME incl. billet premium | K3: =M3+M4 -> 5.61 | M3: 5.1 | N3: LME | S3: Section | T3: Basic Material | U3: Length | V3: Weight/m | W3: MPG | X3: MPM Surcharge | Y3: Roll? | Z3: Rolling Factor (Cost/0.8*2.5) | AA3: List Price | AB3: TOTAL COST | AC3: Metal Sell Price | AD3: Actual Margin % | AF3: Section | AG3: Material | AH3: NEW COST | AI3: OLD COST | AJ3: OLD COST | AK3: OLD COST | AL3: OLD COST | AM3: OLD COST | AN3: OLD COST | AO3: OLD COST | AP3: OLD COST | AQ3: OLD COST | AR3: OLD COST | AS3: OLD COST | AT3: OLD COST
A4: Internal Spread | B4: =Table_Costs[[#This Row],[Value]] -> 3.12 | D4: =TEXT(MONTH(C3),"00") & "." -> 06. | E4: Metal Cost | F4: =B5+F3 -> 9.08 | G4: $/kg | J4: Spread | K4: 3.12 | L4: 500-999kg spread | M4: 0.51 | N4: Billet Prem | S4: ETB0001 | T4: =VLOOKUP(Table_TB_Cost[[#This Row],[Section]],DATA!A:K,2,FALSE) -> 425TB - Solid Mullion / Frame | U4: 6.5 | V4: =VLOOKUP(Table_TB_Cost[[#This Row],[Section]],DATA!A:K,4,FALSE) -> 2.347 | W4: =LEFT(VLOOKUP(Table_TB_Cost[[#This Row],[Section]],Table5[],10,FALSE),2) -> FJ | X4: =IF(Table_TB_Cost[[#This Row],[Weight/m]]<0.5,1*2.5,"") | Y4: Y | Z4: =IF(Table_TB_Cost[[#This Row],[Roll?]]="Y",(2.5/Table_TB_Cost[[#This Row],[Weight/m]]/0.8)*2.5,"") -> 3.3287175 | AA4: =SUM(VLOOKUP(Table_TB_Cost[[#This Row],[MPG]],TB_MPG,2,FALSE),Table_TB_Cost[[#This Row],[MPM Surcharge]],Table_TB_Cost[[#This Row],[Rolling Factor (Cost/0.8*2.5)]])*Table_TB_Cost[[#This Row],[Weight/m]]*Table_TB_Cost[[#This Row],[Length]] -> 584.87631 | AB4: =VLOOKUP(Table_TB_Cost[[#This Row],[Section]],AF:AJ,3,FALSE) -> 157.138 | AC4: =IF($AB$2="Margin",Table_TB_Cost[[#This Row],[TOTAL COST]]/(1-$AC$2),Table_TB_Cost[[#This Row],[List Price]]*(1-$AC$2)) -> 314.276 | AD4: =(Table_TB_Cost[[#This Row],[Metal Sell Price]]-Table_TB_Cost[[#This Row],[TOTAL COST]])/Table_TB_Cost[[#This Row],[Metal Sell Price]] -> 0.5 | AF4: ETB0001 | AG4: 734490 | AH4: 157.138 | AI4: 149.1742 | AJ4: 149.48989 | AK4: 145.03968 | AL4: 142.61705 | AM4: 145.27077 | AN4: 162.04271 | AO4: 177.15902 | AP4: 149.1 | AQ4: 134.3 | AR4: 137.06 | AS4: 138.41 | AT4: 143 | AW4: =VLOOKUP(AF4,Table_TB_Cost[[Section]:[Basic Material]],2,FALSE) -> 425TB - Solid Mullion / Frame | AX4: ETB0001 | AY4: =VLOOKUP(AX4,Table_TB_Cost[#All],5,FALSE) -> FJ
